Traceback (most recent call last):
  File "/Users/jirlong/opt/anaconda3/lib/python3.9/site-packages/jupyter_cache/executors/utils.py", line 58, in single_nb_execution
    executenb(
  File "/Users/jirlong/opt/anaconda3/lib/python3.9/site-packages/nbclient/client.py", line 1204, in execute
    return NotebookClient(nb=nb, resources=resources, km=km, **kwargs).execute()
  File "/Users/jirlong/opt/anaconda3/lib/python3.9/site-packages/nbclient/util.py", line 84, in wrapped
    return just_run(coro(*args, **kwargs))
  File "/Users/jirlong/opt/anaconda3/lib/python3.9/site-packages/nbclient/util.py", line 62, in just_run
    return loop.run_until_complete(coro)
  File "/Users/jirlong/opt/anaconda3/lib/python3.9/asyncio/base_events.py", line 647, in run_until_complete
    return future.result()
  File "/Users/jirlong/opt/anaconda3/lib/python3.9/site-packages/nbclient/client.py", line 663, in async_execute
    await self.async_execute_cell(
  File "/Users/jirlong/opt/anaconda3/lib/python3.9/site-packages/nbclient/client.py", line 965, in async_execute_cell
    await self._check_raise_for_error(cell, cell_index, exec_reply)
  File "/Users/jirlong/opt/anaconda3/lib/python3.9/site-packages/nbclient/client.py", line 862, in _check_raise_for_error
    raise CellExecutionError.from_cell_and_msg(cell, exec_reply_content)
nbclient.exceptions.CellExecutionError: An error occurred while executing the following cell:
------------------
import pandas as pd

li = [(u1, u2, user_pair_counts[(u1, u2)], mi) for (u1, u2), mi in pmi_scores.most_common()]
df = pd.DataFrame.from_records(li, columns =['u1', 'u2', 'count', 'mi'])
df
------------------

[0;31m---------------------------------------------------------------------------[0m
[0;31mNameError[0m                                 Traceback (most recent call last)
Input [0;32mIn [8][0m, in [0;36m<cell line: 3>[0;34m()[0m
[1;32m      1[0m [38;5;28;01mimport[39;00m [38;5;21;01mpandas[39;00m [38;5;28;01mas[39;00m [38;5;21;01mpd[39;00m
[0;32m----> 3[0m li [38;5;241m=[39m [(u1, u2, user_pair_counts[(u1, u2)], mi) [38;5;28;01mfor[39;00m (u1, u2), mi [38;5;129;01min[39;00m [43mpmi_scores[49m[38;5;241m.[39mmost_common()]
[1;32m      4[0m df [38;5;241m=[39m pd[38;5;241m.[39mDataFrame[38;5;241m.[39mfrom_records(li, columns [38;5;241m=[39m[[38;5;124m'[39m[38;5;124mu1[39m[38;5;124m'[39m, [38;5;124m'[39m[38;5;124mu2[39m[38;5;124m'[39m, [38;5;124m'[39m[38;5;124mcount[39m[38;5;124m'[39m, [38;5;124m'[39m[38;5;124mmi[39m[38;5;124m'[39m])
[1;32m      5[0m df

[0;31mNameError[0m: name 'pmi_scores' is not defined
NameError: name 'pmi_scores' is not defined

