Traceback (most recent call last):
  File "/Users/jirlong/opt/anaconda3/lib/python3.9/site-packages/jupyter_cache/executors/utils.py", line 58, in single_nb_execution
    executenb(
  File "/Users/jirlong/opt/anaconda3/lib/python3.9/site-packages/nbclient/client.py", line 1204, in execute
    return NotebookClient(nb=nb, resources=resources, km=km, **kwargs).execute()
  File "/Users/jirlong/opt/anaconda3/lib/python3.9/site-packages/nbclient/util.py", line 84, in wrapped
    return just_run(coro(*args, **kwargs))
  File "/Users/jirlong/opt/anaconda3/lib/python3.9/site-packages/nbclient/util.py", line 62, in just_run
    return loop.run_until_complete(coro)
  File "/Users/jirlong/opt/anaconda3/lib/python3.9/asyncio/base_events.py", line 647, in run_until_complete
    return future.result()
  File "/Users/jirlong/opt/anaconda3/lib/python3.9/site-packages/nbclient/client.py", line 663, in async_execute
    await self.async_execute_cell(
  File "/Users/jirlong/opt/anaconda3/lib/python3.9/site-packages/nbclient/client.py", line 965, in async_execute_cell
    await self._check_raise_for_error(cell, cell_index, exec_reply)
  File "/Users/jirlong/opt/anaconda3/lib/python3.9/site-packages/nbclient/client.py", line 862, in _check_raise_for_error
    raise CellExecutionError.from_cell_and_msg(cell, exec_reply_content)
nbclient.exceptions.CellExecutionError: An error occurred while executing the following cell:
------------------
from IPython.display import display
pd.options.display.float_format = '{:.4f}'.format

import warnings
warnings.filterwarnings("ignore", message=".*The 'nopython' keyword.*")
# import os
# os.environ["TOKENIZERS_PARALLELISM"] = "false"

import re
import zhon.hanzi
from collections import Counter
zh_pat = f"[{zhon.hanzi.characters}|{zhon.hanzi.punctuation}]"

with open("data/stopwords_zh-tw.txt", encoding="utf-8") as fin:
    stopwords = fin.read().split("\n")[1:]
------------------

[0;31m---------------------------------------------------------------------------[0m
[0;31mNameError[0m                                 Traceback (most recent call last)
Input [0;32mIn [1][0m, in [0;36m<cell line: 2>[0;34m()[0m
[1;32m      1[0m [38;5;28;01mfrom[39;00m [38;5;21;01mIPython[39;00m[38;5;21;01m.[39;00m[38;5;21;01mdisplay[39;00m [38;5;28;01mimport[39;00m display
[0;32m----> 2[0m [43mpd[49m[38;5;241m.[39moptions[38;5;241m.[39mdisplay[38;5;241m.[39mfloat_format [38;5;241m=[39m [38;5;124m'[39m[38;5;132;01m{:.4f}[39;00m[38;5;124m'[39m[38;5;241m.[39mformat
[1;32m      4[0m [38;5;28;01mimport[39;00m [38;5;21;01mwarnings[39;00m
[1;32m      5[0m warnings[38;5;241m.[39mfilterwarnings([38;5;124m"[39m[38;5;124mignore[39m[38;5;124m"[39m, message[38;5;241m=[39m[38;5;124m"[39m[38;5;124m.*The [39m[38;5;124m'[39m[38;5;124mnopython[39m[38;5;124m'[39m[38;5;124m keyword.*[39m[38;5;124m"[39m)

[0;31mNameError[0m: name 'pd' is not defined
NameError: name 'pd' is not defined

